Workbook

Sheet Annual 2023 SCR
B1: Summary per sub-modules
B2: Market Risk Module | D2: Annual 2023
B3: Interest | D3: 874144.04
B4: Equity | D4: 594263.53
B5: Property | D5: 0
B6: Spread | D6: 328569.46
B7: Currency | D7: 7689839.4
B8: Concentration | D8: 485172.03
B9: Diversified | D9: 8233855.4
B11: Counterparty Default Module | D11: =+D2 -> Annual 2023
B12: Type 1 | D12: 12531344
B13: Type 2 | D13: 12340929
B14: Diversified | D14: 23265978
B16: Non-Life UW Module | D16: =+D11 -> Annual 2023
B17: P&R | D17: 12340251
B18: Lapse | D18: 0
B19: CAT | D19: 6229224.1
B20: Diversified | D20: 15149921
B22: Life UW Module | D22: =+D16 -> Annual 2023
B23: Mortality risk | D23: 599636.95
B24: Longevity risk | D24: 0
B25: Disability-morbidity risk | D25: 684238.6
B26: Mass Lapse risk | D26: 436058.42
B27: Life expense risk | D27: 144468.17
B28: Revision risk | D28: 0
B29: Life catastrophe risk | D29: 2161439.5
B30: Diversified | D30: 2852330.8
B32: Health UW Module | D32: =+D22 -> Annual 2023
B33: P&R | D33: 184352.07
B34: CAT | D34: 0
B35: Diversified | D35: 184352.07
B39: Summary per module
B40: Module | D40: =+D32 -> Annual 2023
B41: SCR Market | D41: 8233855.4
B42: SCR CDR | D42: 23265978
B43: SCR Life UW | D43: 2852330.8
B44: SCR Health UW | D44: 184352.07
B45: SCR Non-Life UW | D45: 15149921
B46: Diversified BSCR | D46: 37490207
B49: Operational Risk | D49: 5557503.8
...

Sheet Q1 2024 SCR
B1: Summary per sub-modules
B2: Market Risk Module | C2: Annual 2023 | D2: Q1 2024 | E2: Delta
B3: Interest | C3: =+'Annual 2023 SCR'!D3 -> 874144.04 | D3: 2373585.6 | E3: =+D3-C3 -> 1499441.5
B4: Equity | C4: =+'Annual 2023 SCR'!D4 -> 594263.53 | D4: 514660.92 | E4: =+D4-C4 -> -79602.607
B5: Property | C5: =+'Annual 2023 SCR'!D5 -> 0 | D5: 0 | E5: =+D5-C5 -> 0
B6: Spread | C6: =+'Annual 2023 SCR'!D6 -> 328569.46 | D6: 121491.28 | E6: =+D6-C6 -> -207078.18
B7: Currency | C7: =+'Annual 2023 SCR'!D7 -> 7689839.4 | D7: 6040562.6 | E7: =+D7-C7 -> -1649276.8
B8: Concentration | C8: =+'Annual 2023 SCR'!D8 -> 485172.03 | D8: 53011.654 | E8: =+D8-C8 -> -432160.38
B9: Diversified | C9: =+'Annual 2023 SCR'!D9 -> 8233855.4 | D9: 7182534.1 | E9: =+D9-C9 -> -1051321.2
B11: Counterparty Default Module | C11: =+C2 -> Annual 2023 | D11: =+D2 -> Q1 2024 | E11: Delta
B12: Type 1 | C12: =+'Annual 2023 SCR'!D12 -> 12531344 | D12: 10564215 | E12: =+D12-C12 -> -1967129.4
B13: Type 2 | C13: =+'Annual 2023 SCR'!D13 -> 12340929 | D13: 15978077 | E13: =+D13-C13 -> 3637148.3
B14: Diversified | C14: =+'Annual 2023 SCR'!D14 -> 23265978 | D14: 24901714 | E14: =+D14-C14 -> 1635735.3
B16: Non-Life UW Module | C16: =+C11 -> Annual 2023 | D16: =+D11 -> Q1 2024 | E16: Delta
B17: P&R | C17: =+'Annual 2023 SCR'!D17 -> 12340251 | D17: 11243144 | E17: =+D17-C17 -> -1097106.4
B18: Lapse | C18: =+'Annual 2023 SCR'!D18 -> 0 | D18: 0 | E18: =+D18-C18 -> 0
B19: CAT | C19: =+'Annual 2023 SCR'!D19 -> 6229224.1 | D19: 5338439.7 | E19: =+D19-C19 -> -890784.4
B20: Diversified | C20: =+'Annual 2023 SCR'!D20 -> 15149921 | D20: 13598443 | E20: =+D20-C20 -> -1551478.1
B22: Life UW Module | C22: =+C16 -> Annual 2023 | D22: =+D16 -> Q1 2024 | E22: Delta
B23: Mortality risk | C23: =+'Annual 2023 SCR'!D23 -> 599636.95 | D23: 1572012 | E23: =+D23-C23 -> 972375.02
B24: Longevity risk | C24: =+'Annual 2023 SCR'!D24 -> 0 | D24: 0 | E24: =+D24-C24 -> 0
B25: Disability-morbidity risk | C25: =+'Annual 2023 SCR'!D25 -> 684238.6 | D25: 765136.2 | E25: =+D25-C25 -> 80897.597
B26: Mass Lapse risk | C26: =+'Annual 2023 SCR'!D26 -> 436058.42 | D26: 287742.48 | E26: =+D26-C26 -> -148315.94
B27: Life expense risk | C27: =+'Annual 2023 SCR'!D27 -> 144468.17 | D27: 144468.17 | E27: =+D27-C27 -> 0.001588583
B28: Revision risk | C28: =+'Annual 2023 SCR'!D28 -> 0 | D28: 0 | E28: =+D28-C28 -> 0
B29: Life catastrophe risk | C29: =+'Annual 2023 SCR'!D29 -> 2161439.5 | D29: 1735068 | E29: =+D29-C29 -> -426371.5
B30: Diversified | C30: =+'Annual 2023 SCR'!D30 -> 2852330.8 | D30: 3072516.5 | E30: =+D30-C30 -> 220185.74
B32: Health UW Module | C32: =+C22 -> Annual 2023 | D32: =+D22 -> Q1 2024 | E32: Delta
B33: P&R | C33: =+'Annual 2023 SCR'!D33 -> 184352.07 | D33: 10800.928 | E33: =+D33-C33 -> -173551.14
B34: CAT | C34: =+'Annual 2023 SCR'!D34 -> 0 | D34: 0 | E34: =+D34-C34 -> 0
B35: Diversified | C35: =+'Annual 2023 SCR'!D35 -> 184352.07 | D35: 10800.928 | E35: =+D35-C35 -> -173551.14
B39: Summary per module
B40: Module | C40: =+C32 -> Annual 2023 | D40: =+D32 -> Q1 2024 | E40: Delta
B41: SCR Market | C41: =+'Annual 2023 SCR'!D41 -> 8233855.4 | D41: 7182534.1 | E41: =+D41-C41 -> -1051321.2
B42: SCR CDR | C42: =+'Annual 2023 SCR'!D42 -> 23265978 | D42: 24901714 | E42: =+D42-C42 -> 1635735.3
B43: SCR Life UW | C43: =+'Annual 2023 SCR'!D43 -> 2852330.8 | D43: 3072516.5 | E43: =+D43-C43 -> 220185.74
B44: SCR Health UW | C44: =+'Annual 2023 SCR'!D44 -> 184352.07 | D44: 10800.928 | E44: =+D44-C44 -> -173551.14
B45: SCR Non-Life UW | C45: =+'Annual 2023 SCR'!D45 -> 15149921 | D45: 13598443 | E45: =+D45-C45 -> -1551478.1
B46: Diversified BSCR | C46: =+'Annual 2023 SCR'!D46 -> 37490207 | D46: 37315020 | E46: =+D46-C46 -> -175187.57
B49: Operational Risk | C49: =+'Annual 2023 SCR'!D49 -> 5557503.8 | D49: 5183192.2 | E49: =+D49-C49 -> -374311.55
...

Sheet Q2 2024 SCR
B1: Summary per sub-modules
B2: Market Risk Module | C2: Q1 2024 | D2: Q2 2024 | E2: Delta
B3: Interest | C3: =+'Q1 2024 SCR'!D3 -> 2373585.6 | D3: 2793350.5 | E3: =+D3-C3 -> 419764.98
B4: Equity | C4: =+'Q1 2024 SCR'!D4 -> 514660.92 | D4: 602417.77 | E4: =+D4-C4 -> 87756.847
B5: Property | C5: =+'Q1 2024 SCR'!D5 -> 0 | D5: 0 | E5: =+D5-C5 -> 0
B6: Spread | C6: =+'Q1 2024 SCR'!D6 -> 121491.28 | D6: 113981.11 | E6: =+D6-C6 -> -7510.175
B7: Currency | C7: =+'Q1 2024 SCR'!D7 -> 6040562.6 | D7: 9860504.1 | E7: =+D7-C7 -> 3819941.4
B8: Concentration | C8: =+'Q1 2024 SCR'!D8 -> 53011.654 | D8: 59228.139 | E8: =+D8-C8 -> 6216.4849
B9: Diversified | C9: =+'Q1 2024 SCR'!D9 -> 7182534.1 | D9: 11082360 | E9: =+D9-C9 -> 3899825.7
B11: Counterparty Default Module | C11: =+C2 -> Q1 2024 | D11: =+D2 -> Q2 2024 | E11: Delta
B12: Type 1 | C12: =+'Q1 2024 SCR'!D12 -> 10564215 | D12: 11975467 | E12: =+D12-C12 -> 1411252.7
B13: Type 2 | C13: =+'Q1 2024 SCR'!D13 -> 15978077 | D13: 15258712 | E13: =+D13-C13 -> -719364.87
B14: Diversified | C14: =+'Q1 2024 SCR'!D14 -> 24901714 | D14: 25501675 | E14: =+D14-C14 -> 599961.64
B16: Non-Life UW Module | C16: =+C11 -> Q1 2024 | D16: =+D11 -> Q2 2024 | E16: Delta
B17: P&R | C17: =+'Q1 2024 SCR'!D17 -> 11243144 | D17: 11980770 | E17: =+D17-C17 -> 737625.78
B18: Lapse | C18: =+'Q1 2024 SCR'!D18 -> 0 | D18: 0 | E18: =+D18-C18 -> 0
B19: CAT | C19: =+'Q1 2024 SCR'!D19 -> 5338439.7 | D19: 5797026.8 | E19: =+D19-C19 -> 458587.17
B20: Diversified | C20: =+'Q1 2024 SCR'!D20 -> 13598443 | D20: 14555782 | E20: =+D20-C20 -> 957339.05
B22: Life UW Module | C22: =+C16 -> Q1 2024 | D22: =+D16 -> Q2 2024 | E22: Delta
B23: Mortality risk | C23: =+'Q1 2024 SCR'!D23 -> 1572012 | D23: 825842.39 | E23: =+D23-C23 -> -746169.58
B24: Longevity risk | C24: =+'Q1 2024 SCR'!D24 -> 0 | D24: 0 | E24: =+D24-C24 -> 0
B25: Disability-morbidity risk | C25: =+'Q1 2024 SCR'!D25 -> 765136.2 | D25: 610173.05 | E25: =+D25-C25 -> -154963.15
B26: Mass Lapse risk | C26: =+'Q1 2024 SCR'!D26 -> 287742.48 | D26: 220271.17 | E26: =+D26-C26 -> -67471.305
B27: Life expense risk | C27: =+'Q1 2024 SCR'!D27 -> 144468.17 | D27: 142580.15 | E27: =+D27-C27 -> -1888.018
B28: Revision risk | C28: =+'Q1 2024 SCR'!D28 -> 0 | D28: 0 | E28: =+D28-C28 -> 0
B29: Life catastrophe risk | C29: =+'Q1 2024 SCR'!D29 -> 1735068 | D29: 7891.4867 | E29: =+D29-C29 -> -1727176.6
B30: Diversified | C30: =+'Q1 2024 SCR'!D30 -> 3072516.5 | D30: 1248826.7 | E30: =+D30-C30 -> -1823689.9
B32: Health UW Module | C32: =+C22 -> Q1 2024 | D32: =+D22 -> Q2 2024 | E32: Delta
B33: P&R | C33: =+'Q1 2024 SCR'!D33 -> 10800.928 | D33: 1182.2288 | E33: =+D33-C33 -> -9618.6991
B34: CAT | C34: =+'Q1 2024 SCR'!D34 -> 0 | D34: 0 | E34: =+D34-C34 -> 0
B35: Diversified | C35: =+'Q1 2024 SCR'!D35 -> 10800.928 | D35: 1182.2288 | E35: =+D35-C35 -> -9618.6991
B39: Summary per module
B40: Module | C40: =+C32 -> Q1 2024 | D40: =+D32 -> Q2 2024 | E40: Delta
B41: SCR Market | C41: =+'Q1 2024 SCR'!D41 -> 7182534.1 | D41: 11082360 | E41: =+D41-C41 -> 3899825.7
B42: SCR CDR | C42: =+'Q1 2024 SCR'!D42 -> 24901714 | D42: 25501675 | E42: =+D42-C42 -> 599961.64
B43: SCR Life UW | C43: =+'Q1 2024 SCR'!D43 -> 3072516.5 | D43: 1248826.7 | E43: =+D43-C43 -> -1823689.9
B44: SCR Health UW | C44: =+'Q1 2024 SCR'!D44 -> 10800.928 | D44: 1182.2288 | E44: =+D44-C44 -> -9618.6991
B45: SCR Non-Life UW | C45: =+'Q1 2024 SCR'!D45 -> 13598443 | D45: 14555782 | E45: =+D45-C45 -> 957339.05
B46: Diversified BSCR | C46: =+'Q1 2024 SCR'!D46 -> 37315020 | D46: 40032647 | E46: =+D46-C46 -> 2717627.4
B49: Operational Risk | C49: =+'Q1 2024 SCR'!D49 -> 5183192.2 | D49: 5972583 | E49: =+D49-C49 -> 789390.79
...

Sheet Q3 2024 SCR
B1: Summary per sub-modules
B2: Market Risk Module | C2: Q2 2024 | D2: Q3 2024 | E2: Delta
B3: Interest | C3: =+'Q2 2024 SCR'!D3 -> 2793350.5 | D3: 2407319.6 | E3: =+D3-C3 -> -386030.98
B4: Equity | C4: =+'Q2 2024 SCR'!D4 -> 602417.77 | D4: 570462.89 | E4: =+D4-C4 -> -31954.877
B5: Property | C5: =+'Q2 2024 SCR'!D5 -> 0 | D5: 0 | E5: =+D5-C5 -> 0
B6: Spread | C6: =+'Q2 2024 SCR'!D6 -> 113981.11 | D6: 111173.29 | E6: =+D6-C6 -> -2807.8173
B7: Currency | C7: =+'Q2 2024 SCR'!D7 -> 9860504.1 | D7: 7085730.6 | E7: =+D7-C7 -> -2774773.5
B8: Concentration | C8: =+'Q2 2024 SCR'!D8 -> 59228.139 | D8: 53118.609 | E8: =+D8-C8 -> -6109.5295
B9: Diversified | C9: =+'Q2 2024 SCR'!D9 -> 11082360 | D9: 8308018.7 | E9: =+D9-C9 -> -2774341.2
B11: Counterparty Default Module | C11: =+C2 -> Q2 2024 | D11: =+D2 -> Q3 2024 | E11: Delta
B12: Type 1 | C12: =+'Q2 2024 SCR'!D12 -> 11975467 | D12: 8708313.7 | E12: =+D12-C12 -> -3267153.7
B13: Type 2 | C13: =+'Q2 2024 SCR'!D13 -> 15258712 | D13: 15149437 | E13: =+D13-C13 -> -109275.06
B14: Diversified | C14: =+'Q2 2024 SCR'!D14 -> 25501675 | D14: 22432772 | E14: =+D14-C14 -> -3068903.3
B16: Non-Life UW Module | C16: =+C11 -> Q2 2024 | D16: =+D11 -> Q3 2024 | E16: Delta
B17: P&R | C17: =+'Q2 2024 SCR'!D17 -> 11980770 | D17: 11382818 | E17: =+D17-C17 -> -597951.53
B18: Lapse | C18: =+'Q2 2024 SCR'!D18 -> 0 | D18: 0 | E18: =+D18-C18 -> 0
B19: CAT | C19: =+'Q2 2024 SCR'!D19 -> 5797026.8 | D19: 6157401.5 | E19: =+D19-C19 -> 360374.7
B20: Diversified | C20: =+'Q2 2024 SCR'!D20 -> 14555782 | D20: 14231179 | E20: =+D20-C20 -> -324603.58
B22: Life UW Module | C22: =+C16 -> Q2 2024 | D22: =+D16 -> Q3 2024 | E22: Delta
B23: Mortality risk | C23: =+'Q2 2024 SCR'!D23 -> 825842.39 | D23: 807128.09 | E23: =+D23-C23 -> -18714.3
B24: Longevity risk | C24: =+'Q2 2024 SCR'!D24 -> 0 | D24: 0 | E24: =+D24-C24 -> 0
B25: Disability-morbidity risk | C25: =+'Q2 2024 SCR'!D25 -> 610173.05 | D25: 748507.84 | E25: =+D25-C25 -> 138334.8
B26: Mass Lapse risk | C26: =+'Q2 2024 SCR'!D26 -> 220271.17 | D26: 145951.51 | E26: =+D26-C26 -> -74319.663
B27: Life expense risk | C27: =+'Q2 2024 SCR'!D27 -> 142580.15 | D27: 71557.156 | E27: =+D27-C27 -> -71022.996
B28: Revision risk | C28: =+'Q2 2024 SCR'!D28 -> 0 | D28: 0 | E28: =+D28-C28 -> 0
B29: Life catastrophe risk | C29: =+'Q2 2024 SCR'!D29 -> 7891.4867 | D29: 2578848.4 | E29: =+D29-C29 -> 2570956.9
B30: Diversified | C30: =+'Q2 2024 SCR'!D30 -> 1248826.7 | D30: 3251136.8 | E30: =+D30-C30 -> 2002310.1
B32: Health UW Module | C32: =+C22 -> Q2 2024 | D32: =+D22 -> Q3 2024 | E32: Delta
B33: P&R | C33: =+'Q2 2024 SCR'!D33 -> 1182.2288 | D33: 891.22211 | E33: =+D33-C33 -> -291.00671
B34: CAT | C34: =+'Q2 2024 SCR'!D34 -> 0 | D34: 0 | E34: =+D34-C34 -> 0
B35: Diversified | C35: =+'Q2 2024 SCR'!D35 -> 1182.2288 | D35: 891.22211 | E35: =+D35-C35 -> -291.00671
B39: Summary per module
B40: Module | C40: =+C32 -> Q2 2024 | D40: =+D32 -> Q3 2024 | E40: Delta
B41: SCR Market | C41: =+'Q2 2024 SCR'!D41 -> 11082360 | D41: 8308018.7 | E41: =+D41-C41 -> -2774341.2
B42: SCR CDR | C42: =+'Q2 2024 SCR'!D42 -> 25501675 | D42: 22432772 | E42: =+D42-C42 -> -3068903.3
B43: SCR Life UW | C43: =+'Q2 2024 SCR'!D43 -> 1248826.7 | D43: 3251136.8 | E43: =+D43-C43 -> 2002310.1
B44: SCR Health UW | C44: =+'Q2 2024 SCR'!D44 -> 1182.2288 | D44: 891.22211 | E44: =+D44-C44 -> -291.00671
B45: SCR Non-Life UW | C45: =+'Q2 2024 SCR'!D45 -> 14555782 | D45: 14231179 | E45: =+D45-C45 -> -324603.58
B46: Diversified BSCR | C46: =+'Q2 2024 SCR'!D46 -> 40032647 | D46: 36150828 | E46: =+D46-C46 -> -3881819.4
B49: Operational Risk | C49: =+'Q2 2024 SCR'!D49 -> 5972583 | D49: 7075055.7 | E49: =+D49-C49 -> 1102472.7
...

Sheet Q4 2024 SCR
B1: Summary per sub-modules
B2: Market Risk Module | C2: Q3 2024 | D2: Q4 2024 | E2: Delta
B3: Interest | C3: =+'Q3 2024 SCR'!D3 -> 2407319.6 | D3: 332435.7 | E3: =+D3-C3 -> -2074883.9
B4: Equity | C4: =+'Q3 2024 SCR'!D4 -> 570462.89 | D4: 674028.17 | E4: =+D4-C4 -> 103565.29
B5: Property | C5: =+'Q3 2024 SCR'!D5 -> 0 | D5: 0 | E5: =+D5-C5 -> 0
B6: Spread | C6: =+'Q3 2024 SCR'!D6 -> 111173.29 | D6: 90491.784 | E6: =+D6-C6 -> -20681.508
B7: Currency | C7: =+'Q3 2024 SCR'!D7 -> 7085730.6 | D7: 6582811.1 | E7: =+D7-C7 -> -502919.5
B8: Concentration | C8: =+'Q3 2024 SCR'!D8 -> 53118.609 | D8: 71959.887 | E8: =+D8-C8 -> 18841.277
B9: Diversified | C9: =+'Q3 2024 SCR'!D9 -> 8308018.7 | D9: 6918653.5 | E9: =+D9-C9 -> -1389365.2
B11: Counterparty Default Module | C11: =+C2 -> Q3 2024 | D11: =+D2 -> Q4 2024 | E11: Delta
B12: Type 1 | C12: =+'Q3 2024 SCR'!D12 -> 8708313.7 | D12: 9664490.4 | E12: =+D12-C12 -> 956176.65
B13: Type 2 | C13: =+'Q3 2024 SCR'!D13 -> 15149437 | D13: 14136391 | E13: =+D13-C13 -> -1013045.9
B14: Diversified | C14: =+'Q3 2024 SCR'!D14 -> 22432772 | D14: 22319755 | E14: =+D14-C14 -> -113016.97
B16: Non-Life UW Module | C16: =+C11 -> Q3 2024 | D16: =+D11 -> Q4 2024 | E16: Delta
B17: P&R | C17: =+'Q3 2024 SCR'!D17 -> 11382818 | D17: 7299512.2 | E17: =+D17-C17 -> -4083306.3
B18: Lapse | C18: =+'Q3 2024 SCR'!D18 -> 0 | D18: 1800494.8 | E18: =+D18-C18 -> 1800494.8
B19: CAT | C19: =+'Q3 2024 SCR'!D19 -> 6157401.5 | D19: 3578065.9 | E19: =+D19-C19 -> -2579335.6
B20: Diversified | C20: =+'Q3 2024 SCR'!D20 -> 14231179 | D20: 9076689 | E20: =+D20-C20 -> -5154489.5
B22: Life UW Module | C22: =+C16 -> Q3 2024 | D22: =+D16 -> Q4 2024 | E22: Delta
B23: Mortality risk | C23: =+'Q3 2024 SCR'!D23 -> 807128.09 | D23: 277220.84 | E23: =+D23-C23 -> -529907.25
B24: Longevity risk | C24: =+'Q3 2024 SCR'!D24 -> 0 | D24: 0 | E24: =+D24-C24 -> 0
B25: Disability-morbidity risk | C25: =+'Q3 2024 SCR'!D25 -> 748507.84 | D25: 154198.18 | E25: =+D25-C25 -> -594309.66
B26: Mass Lapse risk | C26: =+'Q3 2024 SCR'!D26 -> 145951.51 | D26: 887358.86 | E26: =+D26-C26 -> 741407.35
B27: Life expense risk | C27: =+'Q3 2024 SCR'!D27 -> 71557.156 | D27: 10152.708 | E27: =+D27-C27 -> -61404.448
B28: Revision risk | C28: =+'Q3 2024 SCR'!D28 -> 0 | D28: 0 | E28: =+D28-C28 -> 0
B29: Life catastrophe risk | C29: =+'Q3 2024 SCR'!D29 -> 2578848.4 | D29: 2467164.2 | E29: =+D29-C29 -> -111684.17
B30: Diversified | C30: =+'Q3 2024 SCR'!D30 -> 3251136.8 | D30: 2940703.5 | E30: =+D30-C30 -> -310433.29
B32: Health UW Module | C32: =+C22 -> Q3 2024 | D32: =+D22 -> Q4 2024 | E32: Delta
B33: P&R | C33: =+'Q3 2024 SCR'!D33 -> 891.22211 | D33: 299.439 | E33: =+D33-C33 -> -591.78311
B34: CAT | C34: =+'Q3 2024 SCR'!D34 -> 0 | D34: 220142.56 | E34: =+D34-C34 -> 220142.56
B35: Diversified | C35: =+'Q3 2024 SCR'!D35 -> 891.22211 | D35: 220217.61 | E35: =+D35-C35 -> 219326.39
B39: Summary per module
B40: Module | C40: =+C32 -> Q3 2024 | D40: =+D32 -> Q4 2024 | E40: Delta
B41: SCR Market | C41: =+'Q3 2024 SCR'!D41 -> 8308018.7 | D41: 6918653.5 | E41: =+D41-C41 -> -1389365.2
B42: SCR CDR | C42: =+'Q3 2024 SCR'!D42 -> 22432772 | D42: 22319755 | E42: =+D42-C42 -> -113016.97
B43: SCR Life UW | C43: =+'Q3 2024 SCR'!D43 -> 3251136.8 | D43: 2940703.5 | E43: =+D43-C43 -> -310433.29
B44: SCR Health UW | C44: =+'Q3 2024 SCR'!D44 -> 891.22211 | D44: 220217.61 | E44: =+D44-C44 -> 219326.39
B45: SCR Non-Life UW | C45: =+'Q3 2024 SCR'!D45 -> 14231179 | D45: 9076689 | E45: =+D45-C45 -> -5154489.5
B46: Diversified BSCR | C46: =+'Q3 2024 SCR'!D46 -> 36150828 | D46: 31541334 | E46: =+D46-C46 -> -4609494.1
B49: Operational Risk | C49: =+'Q3 2024 SCR'!D49 -> 7075055.7 | D49: 8923159.1 | E49: =+D49-C49 -> 1848103.4
...

Sheet Annual 2024 SCR
B1: Summary per sub-modules
B2: Market Risk Module | C2: Q4 2024 | D2: Annual 2024 | E2: Delta
B3: Interest | C3: =+'Q4 2024 SCR'!D3 -> 332435.7 | D3: 389180.19 | E3: =+D3-C3 -> 56744.489
B4: Equity | C4: =+'Q4 2024 SCR'!D4 -> 674028.17 | D4: 674028.17 | E4: =+D4-C4 -> 0
B5: Property | C5: =+'Q4 2024 SCR'!D5 -> 0 | D5: 0 | E5: =+D5-C5 -> 0
B6: Spread | C6: =+'Q4 2024 SCR'!D6 -> 90491.784 | D6: 90491.784 | E6: =+D6-C6 -> 0
B7: Currency | C7: =+'Q4 2024 SCR'!D7 -> 6582811.1 | D7: 5109327.4 | E7: =+D7-C7 -> -1473483.7
B8: Concentration | C8: =+'Q4 2024 SCR'!D8 -> 71959.887 | D8: 6226215 | E8: =+D8-C8 -> 6154255.1
B9: Diversified | C9: =+'Q4 2024 SCR'!D9 -> 6918653.5 | D9: 6585249.8 | E9: =+D9-C9 -> -333403.73
B11: Counterparty Default Module | C11: =+C2 -> Q4 2024 | D11: =+D2 -> Annual 2024 | E11: Delta
B12: Type 1 | C12: =+'Q4 2024 SCR'!D12 -> 9664490.4 | D12: 9814418.5 | E12: =+D12-C12 -> 149928.17
B13: Type 2 | C13: =+'Q4 2024 SCR'!D13 -> 14136391 | D13: 14136391 | E13: =+D13-C13 -> 0
B14: Diversified | C14: =+'Q4 2024 SCR'!D14 -> 22319755 | D14: 22455981 | E14: =+D14-C14 -> 136225.61
B16: Non-Life UW Module | C16: =+C11 -> Q4 2024 | D16: =+D11 -> Annual 2024 | E16: Delta
B17: P&R | C17: =+'Q4 2024 SCR'!D17 -> 7299512.2 | D17: 7541058 | E17: =+D17-C17 -> 241545.86
B18: Lapse | C18: =+'Q4 2024 SCR'!D18 -> 1800494.8 | D18: 1800494.8 | E18: =+D18-C18 -> 0
B19: CAT | C19: =+'Q4 2024 SCR'!D19 -> 3578065.9 | D19: 3715643.1 | E19: =+D19-C19 -> 137577.17
B20: Diversified | C20: =+'Q4 2024 SCR'!D20 -> 9076689 | D20: 9376848.1 | E20: =+D20-C20 -> 300159.17
B22: Life UW Module | C22: =+C16 -> Q4 2024 | D22: =+D16 -> Annual 2024 | E22: Delta
B23: Mortality risk | C23: =+'Q4 2024 SCR'!D23 -> 277220.84 | D23: 277220.84 | E23: =+D23-C23 -> 0
B24: Longevity risk | C24: =+'Q4 2024 SCR'!D24 -> 0 | D24: 0 | E24: =+D24-C24 -> 0
B25: Disability-morbidity risk | C25: =+'Q4 2024 SCR'!D25 -> 154198.18 | D25: 154198.18 | E25: =+D25-C25 -> 0
B26: Mass Lapse risk | C26: =+'Q4 2024 SCR'!D26 -> 887358.86 | D26: 887358.86 | E26: =+D26-C26 -> 0
B27: Life expense risk | C27: =+'Q4 2024 SCR'!D27 -> 10152.708 | D27: 10152.708 | E27: =+D27-C27 -> 0
B28: Revision risk | C28: =+'Q4 2024 SCR'!D28 -> 0 | D28: 0 | E28: =+D28-C28 -> 0
B29: Life catastrophe risk | C29: =+'Q4 2024 SCR'!D29 -> 2467164.2 | D29: 2467164.2 | E29: =+D29-C29 -> 0
B30: Diversified | C30: =+'Q4 2024 SCR'!D30 -> 2940703.5 | D30: 2940703.5 | E30: =+D30-C30 -> 0
B32: Health UW Module | C32: =+C22 -> Q4 2024 | D32: =+D22 -> Annual 2024 | E32: Delta
B33: P&R | C33: =+'Q4 2024 SCR'!D33 -> 299.439 | D33: 299.439 | E33: =+D33-C33 -> 0
B34: CAT | C34: =+'Q4 2024 SCR'!D34 -> 220142.56 | D34: 220142.56 | E34: =+D34-C34 -> 0
B35: Diversified | C35: =+'Q4 2024 SCR'!D35 -> 220217.61 | D35: 220217.61 | E35: =+D35-C35 -> 0
B39: Summary per module
B40: Module | C40: =+C32 -> Q4 2024 | D40: =+D32 -> Annual 2024 | E40: Delta
B41: SCR Market | C41: =+'Q4 2024 SCR'!D41 -> 6918653.5 | D41: 6585249.8 | E41: =+D41-C41 -> -333403.73
B42: SCR CDR | C42: =+'Q4 2024 SCR'!D42 -> 22319755 | D42: 22455981 | E42: =+D42-C42 -> 136225.61
B43: SCR Life UW | C43: =+'Q4 2024 SCR'!D43 -> 2940703.5 | D43: 2940703.5 | E43: =+D43-C43 -> 0
B44: SCR Health UW | C44: =+'Q4 2024 SCR'!D44 -> 220217.61 | D44: 220217.61 | E44: =+D44-C44 -> 0
B45: SCR Non-Life UW | C45: =+'Q4 2024 SCR'!D45 -> 9076689 | D45: 9376848.1 | E45: =+D45-C45 -> 300159.17
B46: Diversified BSCR | C46: =+'Q4 2024 SCR'!D46 -> 31541334 | D46: 31715301 | E46: =+D46-C46 -> 173967.02
B49: Operational Risk | C49: =+'Q4 2024 SCR'!D49 -> 8923159.1 | D49: 8923159.1 | E49: =+D49-C49 -> 0
...

Sheet Q1 2025 SCR
B1: Summary per sub-modules
B2: Market Risk Module | C2: Annual 2024 | D2: Q1 2025 | E2: Delta
B3: Interest | C3: =+'Annual 2024 SCR'!D3 -> 389180.19 | D3: 137109.72 | E3: =+D3-C3 -> -252070.47
B4: Equity | C4: =+'Annual 2024 SCR'!D4 -> 674028.17 | D4: 607987.07 | E4: =+D4-C4 -> -66041.108
B5: Property | C5: =+'Annual 2024 SCR'!D5 -> 0 | D5: 0 | E5: =+D5-C5 -> 0
B6: Spread | C6: =+'Annual 2024 SCR'!D6 -> 90491.784 | D6: 155104.27 | E6: =+D6-C6 -> 64612.489
B7: Currency | C7: =+'Annual 2024 SCR'!D7 -> 5109327.4 | D7: 8149864.3 | E7: =+D7-C7 -> 3040536.9
B8: Concentration | C8: =+'Annual 2024 SCR'!D8 -> 6226215 | D8: 401094.3 | E8: =+D8-C8 -> -5825120.7
B9: Diversified | C9: =+'Annual 2024 SCR'!D9 -> 6585249.8 | D9: 8420689.2 | E9: =+D9-C9 -> 1835439.4
B11: Counterparty Default Module | C11: =+C2 -> Annual 2024 | D11: =+D2 -> Q1 2025 | E11: Delta
B12: Type 1 | C12: =+'Annual 2024 SCR'!D12 -> 9814418.5 | D12: 9239694 | E12: =+D12-C12 -> -574724.5
B13: Type 2 | C13: =+'Annual 2024 SCR'!D13 -> 14136391 | D13: 12660604 | E13: =+D13-C13 -> -1475787.5
B14: Diversified | C14: =+'Annual 2024 SCR'!D14 -> 22455981 | D14: 20521525 | E14: =+D14-C14 -> -1934455.4
B16: Non-Life UW Module | C16: =+C11 -> Annual 2024 | D16: =+D11 -> Q1 2025 | E16: Delta
B17: P&R | C17: =+'Annual 2024 SCR'!D17 -> 7541058 | D17: 7226409.3 | E17: =+D17-C17 -> -314648.7
B18: Lapse | C18: =+'Annual 2024 SCR'!D18 -> 1800494.8 | D18: 1236842.5 | E18: =+D18-C18 -> -563652.29
B19: CAT | C19: =+'Annual 2024 SCR'!D19 -> 3715643.1 | D19: 3642868.5 | E19: =+D19-C19 -> -72774.537
B20: Diversified | C20: =+'Annual 2024 SCR'!D20 -> 9376848.1 | D20: 8954534.7 | E20: =+D20-C20 -> -422313.43
B22: Life UW Module | C22: =+C16 -> Annual 2024 | D22: =+D16 -> Q1 2025 | E22: Delta
B23: Mortality risk | C23: =+'Annual 2024 SCR'!D23 -> 277220.84 | D23: 467081.66 | E23: =+D23-C23 -> 189860.82
B24: Longevity risk | C24: =+'Annual 2024 SCR'!D24 -> 0 | D24: 0 | E24: =+D24-C24 -> 0
B25: Disability-morbidity risk | C25: =+'Annual 2024 SCR'!D25 -> 154198.18 | D25: 71965.085 | E25: =+D25-C25 -> -82233.096
B26: Mass Lapse risk | C26: =+'Annual 2024 SCR'!D26 -> 887358.86 | D26: 1975976.5 | E26: =+D26-C26 -> 1088617.6
B27: Life expense risk | C27: =+'Annual 2024 SCR'!D27 -> 10152.708 | D27: 11792.473 | E27: =+D27-C27 -> 1639.765
B28: Revision risk | C28: =+'Annual 2024 SCR'!D28 -> 0 | D28: 0 | E28: =+D28-C28 -> 0
B29: Life catastrophe risk | C29: =+'Annual 2024 SCR'!D29 -> 2467164.2 | D29: 3204977.1 | E29: =+D29-C29 -> 737812.9
B30: Diversified | C30: =+'Annual 2024 SCR'!D30 -> 2940703.5 | D30: 4300319.7 | E30: =+D30-C30 -> 1359616.2
B32: Health UW Module | C32: =+C22 -> Annual 2024 | D32: =+D22 -> Q1 2025 | E32: Delta
B33: P&R | C33: =+'Annual 2024 SCR'!D33 -> 299.439 | D33: 878436.93 | E33: =+D33-C33 -> 878137.49
B34: CAT | C34: =+'Annual 2024 SCR'!D34 -> 220142.56 | D34: 612125.74 | E34: =+D34-C34 -> 391983.18
B35: Diversified | C35: =+'Annual 2024 SCR'!D35 -> 220217.61 | D35: 1189624.4 | E35: =+D35-C35 -> 969406.82
B39: Summary per module
B40: Module | C40: =+C32 -> Annual 2024 | D40: =+D32 -> Q1 2025 | E40: Delta
B41: SCR Market | C41: =+'Annual 2024 SCR'!D41 -> 6585249.8 | D41: 8420689.2 | E41: =+D41-C41 -> 1835439.4
B42: SCR CDR | C42: =+'Annual 2024 SCR'!D42 -> 22455981 | D42: 20521525 | E42: =+D42-C42 -> -1934455.4
B43: SCR Life UW | C43: =+'Annual 2024 SCR'!D43 -> 2940703.5 | D43: 4300319.7 | E43: =+D43-C43 -> 1359616.2
B44: SCR Health UW | C44: =+'Annual 2024 SCR'!D44 -> 220217.61 | D44: 1189624.4 | E44: =+D44-C44 -> 969406.82
B45: SCR Non-Life UW | C45: =+'Annual 2024 SCR'!D45 -> 9376848.1 | D45: 8954534.7 | E45: =+D45-C45 -> -422313.43
B46: Diversified BSCR | C46: =+'Annual 2024 SCR'!D46 -> 31715301 | D46: 31336898 | E46: =+D46-C46 -> -378402.54
B49: Operational Risk | C49: =+'Annual 2024 SCR'!D49 -> 8923159.1 | D49: 7820065.7 | E49: =+D49-C49 -> -1103093.4
...

Sheet Q2 2025 SCR
B1: Summary per sub-modules
B2: Market Risk Module | C2: Q1 2025 | D2: Q2 2025 | E2: Delta | F2: Comment
B3: Interest | C3: =+'Q1 2025 SCR'!D3 -> 137109.72 | D3: 164901.35 | E3: =+D3-C3 -> 27791.634
B4: Equity | C4: =+'Q1 2025 SCR'!D4 -> 607987.07 | D4: 648746.19 | E4: =+D4-C4 -> 40759.129
B5: Property | C5: =+'Q1 2025 SCR'!D5 -> 0 | D5: 0 | E5: =+D5-C5 -> 0
B6: Spread | C6: =+'Q1 2025 SCR'!D6 -> 155104.27 | D6: 143581.86 | E6: =+D6-C6 -> -11522.416
B7: Currency | C7: =+'Q1 2025 SCR'!D7 -> 8149864.3 | D7: 5109327.4 | E7: =+D7-C7 -> -3040536.9 | F7: Currency SCR methodology update.
B8: Concentration | C8: =+'Q1 2025 SCR'!D8 -> 401094.3 | D8: 403301.46 | E8: =+D8-C8 -> 2207.1521
B9: Diversified | C9: =+'Q1 2025 SCR'!D9 -> 8420689.2 | D9: 5427000.6 | E9: =+D9-C9 -> -2993688.6
B11: Counterparty Default Module | C11: =+C2 -> Q1 2025 | D11: Q2 2025 | E11: Delta | F11: Comment
B12: Type 1 | C12: =+'Q1 2025 SCR'!D12 -> 9239694 | D12: 8575011.2 | E12: =+D12-C12 -> -664682.84 | F12: Due to reduced TPs after Premium Provision methodology update.
B13: Type 2 | C13: =+'Q1 2025 SCR'!D13 -> 12660604 | D13: 11040550 | E13: =+D13-C13 -> -1620053.6 | F13: -0.7m reduction in overdue receivables + FX impact (around -1m)
B14: Diversified | C14: =+'Q1 2025 SCR'!D14 -> 20521525 | D14: 18369372 | E14: =+D14-C14 -> -2152153.1
B16: Non-Life UW Module | C16: =+C11 -> Q1 2025 | D16: Q2 2025 | E16: Delta | F16: Comment
B17: P&R | C17: =+'Q1 2025 SCR'!D17 -> 7226409.3 | D17: 6674347.8 | E17: =+D17-C17 -> -552061.52 | F17: reduction of reserves mostly due to EnONS IBNR release plus run-off of earned premiums for DC lines
B18: Lapse | C18: =+'Q1 2025 SCR'!D18 -> 1236842.5 | D18: 1383398.2 | E18: =+D18-C18 -> 146555.72
B19: CAT | C19: =+'Q1 2025 SCR'!D19 -> 3642868.5 | D19: 3834090.9 | E19: =+D19-C19 -> 191222.41 | F19: new reinsurance structure
B20: Diversified | C20: =+'Q1 2025 SCR'!D20 -> 8954534.7 | D20: 8599766.9 | E20: =+D20-C20 -> -354767.81
B22: Life UW Module | C22: =+C16 -> Q1 2025 | D22: Q2 2025 | E22: Delta | F22: Comment
B23: Mortality risk | C23: =+'Q1 2025 SCR'!D23 -> 467081.66 | D23: 490042.79 | E23: =+D23-C23 -> 22961.135
B24: Longevity risk | C24: =+'Q1 2025 SCR'!D24 -> 0 | D24: 0 | E24: =+D24-C24 -> 0
B25: Disability-morbidity risk | C25: =+'Q1 2025 SCR'!D25 -> 71965.085 | D25: 63785.787 | E25: =+D25-C25 -> -8179.2978
B26: Mass Lapse risk | C26: =+'Q1 2025 SCR'!D26 -> 1975976.5 | D26: 518805.51 | E26: =+D26-C26 -> -1457171 | F26: Due to Premium Provision methodology update.
B27: Life expense risk | C27: =+'Q1 2025 SCR'!D27 -> 11792.473 | D27: 21931.744 | E27: =+D27-C27 -> 10139.271
B28: Revision risk | C28: =+'Q1 2025 SCR'!D28 -> 0 | D28: 0 | E28: =+D28-C28 -> 0
B29: Life catastrophe risk | C29: =+'Q1 2025 SCR'!D29 -> 3204977.1 | D29: 3394707.3 | E29: =+D29-C29 -> 189730.2 | F29: CAR increase
B30: Diversified | C30: =+'Q1 2025 SCR'!D30 -> 4300319.7 | D30: 3732229.1 | E30: =+D30-C30 -> -568090.59
B32: Health UW Module | C32: =+C22 -> Q1 2025 | D32: Q2 2025 | E32: Delta | F32: Comment
B33: P&R | C33: =+'Q1 2025 SCR'!D33 -> 878436.93 | D33: 828777.07 | E33: =+D33-C33 -> -49659.865
B34: CAT | C34: =+'Q1 2025 SCR'!D34 -> 612125.74 | D34: 612125.44 | E34: =+D34-C34 -> -0.30021022
B35: Diversified | C35: =+'Q1 2025 SCR'!D35 -> 1189624.4 | D35: 1146833.4 | E35: =+D35-C35 -> -42791.079
B39: Summary per module
B40: Module | C40: =+C32 -> Q1 2025 | D40: Q2 2025 | E40: Delta | F40: Comment
B41: SCR Market | C41: =+'Q1 2025 SCR'!D41 -> 8420689.2 | D41: 5427000.6 | E41: =+D41-C41 -> -2993688.6
B42: SCR CDR | C42: =+'Q1 2025 SCR'!D42 -> 20521525 | D42: 18369372 | E42: =+D42-C42 -> -2152153.1
B43: SCR Life UW | C43: =+'Q1 2025 SCR'!D43 -> 4300319.7 | D43: 3732229.1 | E43: =+D43-C43 -> -568090.59
B44: SCR Health UW | C44: =+'Q1 2025 SCR'!D44 -> 1189624.4 | D44: 1146833.4 | E44: =+D44-C44 -> -42791.079
B45: SCR Non-Life UW | C45: =+'Q1 2025 SCR'!D45 -> 8954534.7 | D45: 8599766.9 | E45: =+D45-C45 -> -354767.81
B46: Diversified BSCR | C46: =+'Q1 2025 SCR'!D46 -> 31336898 | D46: 27339205 | E46: =+D46-C46 -> -3997693.2
B49: Operational Risk | C49: =+'Q1 2025 SCR'!D49 -> 7820065.7 | D49: 6411779.1 | E49: =+D49-C49 -> -1408286.6 | F49: Impact of FX (-0.6m) summing up to the Gross TP reduction due to Premium Provision methodology update + EnONS IBNR release
...

Sheet Q3 2025 SCR
B1: Summary per sub-modules
B2: Market Risk Module | C2: Q2 2025 | D2: Q3 2025 | E2: Delta | F2: Comment
B3: Interest | C3: 164901.35 | D3: 6099.956 | E3: =+D3-C3 -> -158801.4 | F3: Better match between Assets and Liabilities due to a combination of IR curve, Bonds purchase, TP movements
B4: Equity | C4: 648746.19 | D4: 660437.72 | E4: =+D4-C4 -> 11691.53
B5: Property | C5: 0 | D5: 0 | E5: =+D5-C5 -> 0
B6: Spread | C6: 143581.86 | D6: 130552.55 | E6: =+D6-C6 -> -13029.309
B7: Currency | C7: 5109327.4 | D7: 6722201.4 | E7: =+D7-C7 -> 1612874.1 | F7: Increase due to a deteriorated mismatch for INR and SAR, mostly driven by the Fwh mechanism (amounts ceded to Cayman are fully in USD)
B8: Concentration | C8: 403301.46 | D8: 366581.52 | E8: =+D8-C8 -> -36719.932
B9: Diversified | C9: 5427000.6 | D9: 6970573.3 | E9: =+D9-C9 -> 1543572.7
B11: Counterparty Default Module | C11: Q2 2025 | D11: =+D2 -> Q3 2025 | E11: Delta | F11: Comment
B12: Type 1 | C12: 8575011.2 | D12: 8399881.5 | E12: =+D12-C12 -> -175129.68 | F12: Mostly due to a reduced cash position (from EUR 40.3m to EUR 22.0m)
B13: Type 2 | C13: 11040550 | D13: 11462983 | E13: =+D13-C13 -> 422432.72 | F13: Due to a EUR 0.5m increase in overdue receivables (>90 days)
B14: Diversified | C14: 18369372 | D14: 18611543 | E14: =+D14-C14 -> 242171.03
B16: Non-Life UW Module | C16: Q2 2025 | D16: =+D11 -> Q3 2025 | E16: Delta | F16: Comment
B17: P&R | C17: 6674347.8 | D17: 6880373.5 | E17: =+D17-C17 -> 206025.7 | F17: Mostly due to an increase in future expected premiums following new Business plan
B18: Lapse | C18: 1383398.2 | D18: 1154593.8 | E18: =+D18-C18 -> -228804.4 | F18: Mostly due to a decrease in existing UPR/pipeline premiums
B19: CAT | C19: 3834090.9 | D19: 3581804.7 | E19: =+D19-C19 -> -252286.2 | F19: Due to an adjustment in the Property CAT sub-module (driven by new CAT XoL structure)
B20: Diversified | C20: 8599766.9 | D20: 8592091.1 | E20: =+D20-C20 -> -7675.8392
B22: Life UW Module | C22: Q2 2025 | D22: =+D2 -> Q3 2025 | E22: Delta | F22: Comment
B23: Mortality risk | C23: 490042.79 | D23: 465008.75 | E23: =+D23-C23 -> -25034.043
B24: Longevity risk | C24: 0 | D24: 0 | E24: =+D24-C24 -> 0
B25: Disability-morbidity risk | C25: 63785.787 | D25: 201243.58 | E25: =+D25-C25 -> 137457.79 | F25: Due to an increase of the morbidity rate provided by the UW team
B26: Mass Lapse risk | C26: 518805.51 | D26: 280298.84 | E26: =+D26-C26 -> -238506.68 | F26: Mostly due to a decrease in existing UPR/pipeline premiums
B27: Life expense risk | C27: 21931.744 | D27: 20473.731 | E27: =+D27-C27 -> -1458.0132
B28: Revision risk | C28: 0 | D28: 0 | E28: =+D28-C28 -> 0
B29: Life catastrophe risk | C29: 3394707.3 | D29: 2904458.9 | E29: =+D29-C29 -> -490248.45 | F29: Reduction in CAR provided by UW team
B30: Diversified | C30: 3732229.1 | D30: 3199586.1 | E30: =+D30-C30 -> -532642.95
B32: Health UW Module | C32: Q2 2025 | D32: =+D22 -> Q3 2025 | E32: Delta | F32: Comment
B33: P&R | C33: 828777.07 | D33: 932580.44 | E33: =+D33-C33 -> 103803.37
B34: CAT | C34: 612125.44 | D34: 583069.63 | E34: =+D34-C34 -> -29055.809
B35: Diversified | C35: 1146833.4 | D35: 1217191.9 | E35: =+D35-C35 -> 70358.549
B39: Summary per module
B40: Module | C40: Q2 2025 | D40: =+D32 -> Q3 2025 | E40: Delta | F40: Comment
B41: SCR Market | C41: 5427000.6 | D41: =+D9 -> 6970573.3 | E41: =+D41-C41 -> 1543572.7
B42: SCR CDR | C42: 18369372 | D42: =+D14 -> 18611543 | E42: =+D42-C42 -> 242171.03
B43: SCR Life UW | C43: 3732229.1 | D43: =+D30 -> 3199586.1 | E43: =+D43-C43 -> -532642.95
B44: SCR Health UW | C44: 1146833.4 | D44: =+D35 -> 1217191.9 | E44: =+D44-C44 -> 70358.549
B45: SCR Non-Life UW | C45: 8599766.9 | D45: =+D20 -> 8592091.1 | E45: =+D45-C45 -> -7675.8392
B46: Diversified BSCR | C46: 27339205 | D46: 28172476 | E46: =+D46-C46 -> 833271.5 | F46: EUR 0.5m of diversification impact
B49: Operational Risk | C49: 6411779.1 | D49: 6386657 | E49: =+D49-C49 -> -25122.075
...

Sheet Q4 2025 SCR
B1: Summary per sub-modules
B2: Market Risk Module | C2: Q3 2025 | D2: Q4 2025 | E2: Delta | F2: Comment
B3: Interest | C3: 6099.956 | D3: 138617.6 | E3: 132517.64
B4: Equity | C4: 660437.72 | D4: 706595.51 | E4: 46157.783
B5: Property | C5: 0 | D5: 0 | E5: 0
B6: Spread | C6: 130552.55 | D6: 112147.88 | E6: -18404.665
B7: Currency | C7: 6722201.4 | D7: 7468117.8 | E7: 745916.34 | F7: USD mismatch increased by 4m compared to Q3
B8: Concentration | C8: 366581.52 | D8: 365904.48 | E8: -677.04796
B9: Diversified | C9: 6970573.3 | D9: 7761761.2 | E9: 791187.98
B11: Counterparty Default Module | C11: Q3 2025 | D11: Q4 2025 | E11: Delta | F11: Comment
B12: Type 1 | C12: 8399881.5 | D12: 7424530.1 | E12: -975351.41 | F12: 1) inclusion of 5m of minimum FwH deposit as collateral, as per the IntQS contract; 2) better diversification among counterparties; 3) lower ceded provisions due to Bonds novation;
B13: Type 2 | C13: 11462983 | D13: 8753816.8 | E13: -2709166.2 | F13: 3m of lower receivables due to Bonds novation
B14: Diversified | C14: 18611543 | D14: 15140754 | E14: -3470789.5
B16: Non-Life UW Module | C16: Q3 2025 | D16: Q4 2025 | E16: Delta | F16: Comment
B17: P&R | C17: 6880373.5 | D17: 5642399.5 | E17: -1237974 | F17: 1) lower TPs due to bonds novation and 2) lower premiums volumes mostly for Property
B18: Lapse | C18: 1154593.8 | D18: 768572.64 | E18: -386021.15 | F18: following pipeline premiums evolution
B19: CAT | C19: 3581804.7 | D19: 3580571.8 | E19: -1232.9088
B20: Diversified | C20: 8592091.1 | D20: 7439716.3 | E20: -1152374.8
B22: Life UW Module | C22: Q3 2025 | D22: Q4 2025 | E22: Delta | F22: Comment
B23: Mortality risk | C23: 465008.75 | D23: 553532.79 | E23: 88524.039
B24: Longevity risk | C24: 0 | D24: 0 | E24: 0
B25: Disability-morbidity risk | C25: 201243.58 | D25: 132937.65 | E25: -68305.929
B26: Mass Lapse risk | C26: 280298.84 | D26: 264632.14 | E26: -15666.699
B27: Life expense risk | C27: 20473.731 | D27: 17808.912 | E27: -2664.8197
B28: Revision risk | C28: 0 | D28: 0 | E28: 0
B29: Life catastrophe risk | C29: 2904458.9 | D29: 2878720.4 | E29: -25738.525
B30: Diversified | C30: 3199586.1 | D30: 3181959.1 | E30: -17627.031
B32: Health UW Module | C32: Q3 2025 | D32: Q4 2025 | E32: Delta | F32: Comment
B33: P&R | C33: 932580.44 | D33: 1139420.4 | E33: 206839.91
B34: CAT | C34: 583069.63 | D34: 673955.51 | E34: 90885.881
B35: Diversified | C35: 1217191.9 | D35: 1461661.4 | E35: 244469.51
B39: Summary per module
B40: Module | C40: Q3 2025 | D40: Q4 2025 | E40: Delta | F40: Comment
B41: SCR Market | C41: 6970573.3 | D41: 7761761.2 | E41: 791187.98
B42: SCR CDR | C42: 18611543 | D42: 15140754 | E42: -3470789.5
B43: SCR Life UW | C43: 3199586.1 | D43: 3181959.1 | E43: -17627.031
B44: SCR Health UW | C44: 1217191.9 | D44: 1461661.4 | E44: 244469.51
B45: SCR Non-Life UW | C45: 8592091.1 | D45: 7439716.3 | E45: -1152374.8
B46: Diversified BSCR | C46: 28172476 | D46: 24756289 | E46: -3416187.4
B49: Operational Risk | C49: 6386657 | D49: 6157344.6 | E49: -229312.35 | F49: lower TPs mostly due to Bonds novation and IBNR releases compensating MOL loss
...

Sheet Table
B2: Module / Submodule | C2: Annual 2023 | D2: Q1 2024 | E2: Q2 2024 | F2: Q3 2024 | G2: Q4 2024 | H2: Annual 2024 | I2: Q1 2025 | J2: Q2 2025 | K2: Q3 2025 | L2: Q4 2025
B3: Market Risk Module | C3: {=INDIRECT("'"&C$2&" SCR'!D9",1)} -> 8233855.4 | D3: {=INDIRECT("'"&D$2&" SCR'!D9",1)} -> 7182534.1 | E3: {=INDIRECT("'"&E$2&" SCR'!D9",1)} -> 11082360 | F3: {=INDIRECT("'"&F$2&" SCR'!D9",1)} -> 8308018.7 | G3: {=INDIRECT("'"&G$2&" SCR'!D9",1)} -> 6918653.5 | H3: {=INDIRECT("'"&H$2&" SCR'!D9",1)} -> 6585249.8 | I3: {=INDIRECT("'"&I$2&" SCR'!D9",1)} -> 8420689.2 | J3: {=INDIRECT("'"&J$2&" SCR'!D9",1)} -> 5427000.6 | ... L3: {=INDIRECT("'"&L$2&" SCR'!D9",1)} -> 7761761.2
B4: Interest Rate Risk | C4: {=INDIRECT("'"&C$2&" SCR'!D3",1)} -> 874144.04 | D4: {=INDIRECT("'"&D$2&" SCR'!D3",1)} -> 2373585.6 | E4: {=INDIRECT("'"&E$2&" SCR'!D3",1)} -> 2793350.5 | F4: {=INDIRECT("'"&F$2&" SCR'!D3",1)} -> 2407319.6 | G4: {=INDIRECT("'"&G$2&" SCR'!D3",1)} -> 332435.7 | H4: {=INDIRECT("'"&H$2&" SCR'!D3",1)} -> 389180.19 | I4: {=INDIRECT("'"&I$2&" SCR'!D3",1)} -> 137109.72 | J4: {=INDIRECT("'"&J$2&" SCR'!D3",1)} -> 164901.35 | ... L4: {=INDIRECT("'"&L$2&" SCR'!D3",1)} -> 138617.6
B5: Equity Risk | C5: {=INDIRECT("'"&C$2&" SCR'!D4",1)} -> 594263.53 | D5: {=INDIRECT("'"&D$2&" SCR'!D4",1)} -> 514660.92 | E5: {=INDIRECT("'"&E$2&" SCR'!D4",1)} -> 602417.77 | F5: {=INDIRECT("'"&F$2&" SCR'!D4",1)} -> 570462.89 | G5: {=INDIRECT("'"&G$2&" SCR'!D4",1)} -> 674028.17 | H5: {=INDIRECT("'"&H$2&" SCR'!D4",1)} -> 674028.17 | I5: {=INDIRECT("'"&I$2&" SCR'!D4",1)} -> 607987.07 | J5: {=INDIRECT("'"&J$2&" SCR'!D4",1)} -> 648746.19 | ... L5: {=INDIRECT("'"&L$2&" SCR'!D4",1)} -> 706595.51
B6: Property Risk | C6: {=INDIRECT("'"&C$2&" SCR'!D5",1)} -> 0 | D6: {=INDIRECT("'"&D$2&" SCR'!D5",1)} -> 0 | E6: {=INDIRECT("'"&E$2&" SCR'!D5",1)} -> 0 | F6: {=INDIRECT("'"&F$2&" SCR'!D5",1)} -> 0 | G6: {=INDIRECT("'"&G$2&" SCR'!D5",1)} -> 0 | H6: {=INDIRECT("'"&H$2&" SCR'!D5",1)} -> 0 | I6: {=INDIRECT("'"&I$2&" SCR'!D5",1)} -> 0 | J6: {=INDIRECT("'"&J$2&" SCR'!D5",1)} -> 0 | ... L6: {=INDIRECT("'"&L$2&" SCR'!D5",1)} -> 0
B7: Spread Risk | C7: {=INDIRECT("'"&C$2&" SCR'!D6",1)} -> 328569.46 | D7: {=INDIRECT("'"&D$2&" SCR'!D6",1)} -> 121491.28 | E7: {=INDIRECT("'"&E$2&" SCR'!D6",1)} -> 113981.11 | F7: {=INDIRECT("'"&F$2&" SCR'!D6",1)} -> 111173.29 | G7: {=INDIRECT("'"&G$2&" SCR'!D6",1)} -> 90491.784 | H7: {=INDIRECT("'"&H$2&" SCR'!D6",1)} -> 90491.784 | I7: {=INDIRECT("'"&I$2&" SCR'!D6",1)} -> 155104.27 | J7: {=INDIRECT("'"&J$2&" SCR'!D6",1)} -> 143581.86 | ... L7: {=INDIRECT("'"&L$2&" SCR'!D6",1)} -> 112147.88
B8: Currency Risk | C8: {=INDIRECT("'"&C$2&" SCR'!D7",1)} -> 7689839.4 | D8: {=INDIRECT("'"&D$2&" SCR'!D7",1)} -> 6040562.6 | E8: {=INDIRECT("'"&E$2&" SCR'!D7",1)} -> 9860504.1 | F8: {=INDIRECT("'"&F$2&" SCR'!D7",1)} -> 7085730.6 | G8: {=INDIRECT("'"&G$2&" SCR'!D7",1)} -> 6582811.1 | H8: {=INDIRECT("'"&H$2&" SCR'!D7",1)} -> 5109327.4 | I8: {=INDIRECT("'"&I$2&" SCR'!D7",1)} -> 8149864.3 | J8: {=INDIRECT("'"&J$2&" SCR'!D7",1)} -> 5109327.4 | ... L8: {=INDIRECT("'"&L$2&" SCR'!D7",1)} -> 7468117.8
B9: Concentration Risk | C9: {=INDIRECT("'"&C$2&" SCR'!D8",1)} -> 485172.03 | D9: {=INDIRECT("'"&D$2&" SCR'!D8",1)} -> 53011.654 | E9: {=INDIRECT("'"&E$2&" SCR'!D8",1)} -> 59228.139 | F9: {=INDIRECT("'"&F$2&" SCR'!D8",1)} -> 53118.609 | G9: {=INDIRECT("'"&G$2&" SCR'!D8",1)} -> 71959.887 | H9: {=INDIRECT("'"&H$2&" SCR'!D8",1)} -> 6226215 | I9: {=INDIRECT("'"&I$2&" SCR'!D8",1)} -> 401094.3 | J9: {=INDIRECT("'"&J$2&" SCR'!D8",1)} -> 403301.46 | ... L9: {=INDIRECT("'"&L$2&" SCR'!D8",1)} -> 365904.48
B10: Counterparty Default Module | C10: {=INDIRECT("'"&C$2&" SCR'!D14",1)} -> 23265978 | D10: {=INDIRECT("'"&D$2&" SCR'!D14",1)} -> 24901714 | E10: {=INDIRECT("'"&E$2&" SCR'!D14",1)} -> 25501675 | F10: {=INDIRECT("'"&F$2&" SCR'!D14",1)} -> 22432772 | G10: {=INDIRECT("'"&G$2&" SCR'!D14",1)} -> 22319755 | H10: {=INDIRECT("'"&H$2&" SCR'!D14",1)} -> 22455981 | I10: {=INDIRECT("'"&I$2&" SCR'!D14",1)} -> 20521525 | J10: {=INDIRECT("'"&J$2&" SCR'!D14",1)} -> 18369372 | ... L10: {=INDIRECT("'"&L$2&" SCR'!D14",1)} -> 15140754
B11: Type 1 | C11: {=INDIRECT("'"&C$2&" SCR'!D12",1)} -> 12531344 | D11: {=INDIRECT("'"&D$2&" SCR'!D12",1)} -> 10564215 | E11: {=INDIRECT("'"&E$2&" SCR'!D12",1)} -> 11975467 | F11: {=INDIRECT("'"&F$2&" SCR'!D12",1)} -> 8708313.7 | G11: {=INDIRECT("'"&G$2&" SCR'!D12",1)} -> 9664490.4 | H11: {=INDIRECT("'"&H$2&" SCR'!D12",1)} -> 9814418.5 | I11: {=INDIRECT("'"&I$2&" SCR'!D12",1)} -> 9239694 | J11: {=INDIRECT("'"&J$2&" SCR'!D12",1)} -> 8575011.2 | ... L11: {=INDIRECT("'"&L$2&" SCR'!D12",1)} -> 7424530.1
B12: Type 2 | C12: {=INDIRECT("'"&C$2&" SCR'!D13",1)} -> 12340929 | D12: {=INDIRECT("'"&D$2&" SCR'!D13",1)} -> 15978077 | E12: {=INDIRECT("'"&E$2&" SCR'!D13",1)} -> 15258712 | F12: {=INDIRECT("'"&F$2&" SCR'!D13",1)} -> 15149437 | G12: {=INDIRECT("'"&G$2&" SCR'!D13",1)} -> 14136391 | H12: {=INDIRECT("'"&H$2&" SCR'!D13",1)} -> 14136391 | I12: {=INDIRECT("'"&I$2&" SCR'!D13",1)} -> 12660604 | J12: {=INDIRECT("'"&J$2&" SCR'!D13",1)} -> 11040550 | ... L12: {=INDIRECT("'"&L$2&" SCR'!D13",1)} -> 8753816.8
B13: Non-Life UW Module | C13: {=INDIRECT("'"&C$2&" SCR'!D20",1)} -> 15149921 | D13: {=INDIRECT("'"&D$2&" SCR'!D20",1)} -> 13598443 | E13: {=INDIRECT("'"&E$2&" SCR'!D20",1)} -> 14555782 | F13: {=INDIRECT("'"&F$2&" SCR'!D20",1)} -> 14231179 | G13: {=INDIRECT("'"&G$2&" SCR'!D20",1)} -> 9076689 | H13: {=INDIRECT("'"&H$2&" SCR'!D20",1)} -> 9376848.1 | I13: {=INDIRECT("'"&I$2&" SCR'!D20",1)} -> 8954534.7 | J13: {=INDIRECT("'"&J$2&" SCR'!D20",1)} -> 8599766.9 | ... L13: {=INDIRECT("'"&L$2&" SCR'!D20",1)} -> 7439716.3
B14: P&R | C14: {=INDIRECT("'"&C$2&" SCR'!D17",1)} -> 12340251 | D14: {=INDIRECT("'"&D$2&" SCR'!D17",1)} -> 11243144 | E14: {=INDIRECT("'"&E$2&" SCR'!D17",1)} -> 11980770 | F14: {=INDIRECT("'"&F$2&" SCR'!D17",1)} -> 11382818 | G14: {=INDIRECT("'"&G$2&" SCR'!D17",1)} -> 7299512.2 | H14: {=INDIRECT("'"&H$2&" SCR'!D17",1)} -> 7541058 | I14: {=INDIRECT("'"&I$2&" SCR'!D17",1)} -> 7226409.3 | J14: {=INDIRECT("'"&J$2&" SCR'!D17",1)} -> 6674347.8 | ... L14: {=INDIRECT("'"&L$2&" SCR'!D17",1)} -> 5642399.5
B15: Lapse | C15: {=INDIRECT("'"&C$2&" SCR'!D18",1)} -> 0 | D15: {=INDIRECT("'"&D$2&" SCR'!D18",1)} -> 0 | E15: {=INDIRECT("'"&E$2&" SCR'!D18",1)} -> 0 | F15: {=INDIRECT("'"&F$2&" SCR'!D18",1)} -> 0 | G15: {=INDIRECT("'"&G$2&" SCR'!D18",1)} -> 1800494.8 | H15: {=INDIRECT("'"&H$2&" SCR'!D18",1)} -> 1800494.8 | I15: {=INDIRECT("'"&I$2&" SCR'!D18",1)} -> 1236842.5 | J15: {=INDIRECT("'"&J$2&" SCR'!D18",1)} -> 1383398.2 | ... L15: {=INDIRECT("'"&L$2&" SCR'!D18",1)} -> 768572.64
B16: CAT | C16: {=INDIRECT("'"&C$2&" SCR'!D19",1)} -> 6229224.1 | D16: {=INDIRECT("'"&D$2&" SCR'!D19",1)} -> 5338439.7 | E16: {=INDIRECT("'"&E$2&" SCR'!D19",1)} -> 5797026.8 | F16: {=INDIRECT("'"&F$2&" SCR'!D19",1)} -> 6157401.5 | G16: {=INDIRECT("'"&G$2&" SCR'!D19",1)} -> 3578065.9 | H16: {=INDIRECT("'"&H$2&" SCR'!D19",1)} -> 3715643.1 | I16: {=INDIRECT("'"&I$2&" SCR'!D19",1)} -> 3642868.5 | J16: {=INDIRECT("'"&J$2&" SCR'!D19",1)} -> 3834090.9 | ... L16: {=INDIRECT("'"&L$2&" SCR'!D19",1)} -> 3580571.8
B17: Life UW Module | C17: {=INDIRECT("'"&C$2&" SCR'!D30",1)} -> 2852330.8 | D17: {=INDIRECT("'"&D$2&" SCR'!D30",1)} -> 3072516.5 | E17: {=INDIRECT("'"&E$2&" SCR'!D30",1)} -> 1248826.7 | F17: {=INDIRECT("'"&F$2&" SCR'!D30",1)} -> 3251136.8 | G17: {=INDIRECT("'"&G$2&" SCR'!D30",1)} -> 2940703.5 | H17: {=INDIRECT("'"&H$2&" SCR'!D30",1)} -> 2940703.5 | I17: {=INDIRECT("'"&I$2&" SCR'!D30",1)} -> 4300319.7 | J17: {=INDIRECT("'"&J$2&" SCR'!D30",1)} -> 3732229.1 | ... L17: {=INDIRECT("'"&L$2&" SCR'!D30",1)} -> 3181959.1
B18: Mortality risk | C18: {=INDIRECT("'"&C$2&" SCR'!D23",1)} -> 599636.95 | D18: {=INDIRECT("'"&D$2&" SCR'!D23",1)} -> 1572012 | E18: {=INDIRECT("'"&E$2&" SCR'!D23",1)} -> 825842.39 | F18: {=INDIRECT("'"&F$2&" SCR'!D23",1)} -> 807128.09 | G18: {=INDIRECT("'"&G$2&" SCR'!D23",1)} -> 277220.84 | H18: {=INDIRECT("'"&H$2&" SCR'!D23",1)} -> 277220.84 | I18: {=INDIRECT("'"&I$2&" SCR'!D23",1)} -> 467081.66 | J18: {=INDIRECT("'"&J$2&" SCR'!D23",1)} -> 490042.79 | ... L18: {=INDIRECT("'"&L$2&" SCR'!D23",1)} -> 553532.79
B19: Longevity risk | C19: {=INDIRECT("'"&C$2&" SCR'!D24",1)} -> 0 | D19: {=INDIRECT("'"&D$2&" SCR'!D24",1)} -> 0 | E19: {=INDIRECT("'"&E$2&" SCR'!D24",1)} -> 0 | F19: {=INDIRECT("'"&F$2&" SCR'!D24",1)} -> 0 | G19: {=INDIRECT("'"&G$2&" SCR'!D24",1)} -> 0 | H19: {=INDIRECT("'"&H$2&" SCR'!D24",1)} -> 0 | I19: {=INDIRECT("'"&I$2&" SCR'!D24",1)} -> 0 | J19: {=INDIRECT("'"&J$2&" SCR'!D24",1)} -> 0 | ... L19: {=INDIRECT("'"&L$2&" SCR'!D24",1)} -> 0
B20: Disability-morbidity risk | C20: {=INDIRECT("'"&C$2&" SCR'!D25",1)} -> 684238.6 | D20: {=INDIRECT("'"&D$2&" SCR'!D25",1)} -> 765136.2 | E20: {=INDIRECT("'"&E$2&" SCR'!D25",1)} -> 610173.05 | F20: {=INDIRECT("'"&F$2&" SCR'!D25",1)} -> 748507.84 | G20: {=INDIRECT("'"&G$2&" SCR'!D25",1)} -> 154198.18 | H20: {=INDIRECT("'"&H$2&" SCR'!D25",1)} -> 154198.18 | I20: {=INDIRECT("'"&I$2&" SCR'!D25",1)} -> 71965.085 | J20: {=INDIRECT("'"&J$2&" SCR'!D25",1)} -> 63785.787 | ... L20: {=INDIRECT("'"&L$2&" SCR'!D25",1)} -> 132937.65
B21: Mass Lapse risk | C21: {=INDIRECT("'"&C$2&" SCR'!D26",1)} -> 436058.42 | D21: {=INDIRECT("'"&D$2&" SCR'!D26",1)} -> 287742.48 | E21: {=INDIRECT("'"&E$2&" SCR'!D26",1)} -> 220271.17 | F21: {=INDIRECT("'"&F$2&" SCR'!D26",1)} -> 145951.51 | G21: {=INDIRECT("'"&G$2&" SCR'!D26",1)} -> 887358.86 | H21: {=INDIRECT("'"&H$2&" SCR'!D26",1)} -> 887358.86 | I21: {=INDIRECT("'"&I$2&" SCR'!D26",1)} -> 1975976.5 | J21: {=INDIRECT("'"&J$2&" SCR'!D26",1)} -> 518805.51 | ... L21: {=INDIRECT("'"&L$2&" SCR'!D26",1)} -> 264632.14
B22: Life expense risk | C22: {=INDIRECT("'"&C$2&" SCR'!D27",1)} -> 144468.17 | D22: {=INDIRECT("'"&D$2&" SCR'!D27",1)} -> 144468.17 | E22: {=INDIRECT("'"&E$2&" SCR'!D27",1)} -> 142580.15 | F22: {=INDIRECT("'"&F$2&" SCR'!D27",1)} -> 71557.156 | G22: {=INDIRECT("'"&G$2&" SCR'!D27",1)} -> 10152.708 | H22: {=INDIRECT("'"&H$2&" SCR'!D27",1)} -> 10152.708 | I22: {=INDIRECT("'"&I$2&" SCR'!D27",1)} -> 11792.473 | J22: {=INDIRECT("'"&J$2&" SCR'!D27",1)} -> 21931.744 | ... L22: {=INDIRECT("'"&L$2&" SCR'!D27",1)} -> 17808.912
B23: Revision risk | C23: {=INDIRECT("'"&C$2&" SCR'!D28",1)} -> 0 | D23: {=INDIRECT("'"&D$2&" SCR'!D28",1)} -> 0 | E23: {=INDIRECT("'"&E$2&" SCR'!D28",1)} -> 0 | F23: {=INDIRECT("'"&F$2&" SCR'!D28",1)} -> 0 | G23: {=INDIRECT("'"&G$2&" SCR'!D28",1)} -> 0 | H23: {=INDIRECT("'"&H$2&" SCR'!D28",1)} -> 0 | I23: {=INDIRECT("'"&I$2&" SCR'!D28",1)} -> 0 | J23: {=INDIRECT("'"&J$2&" SCR'!D28",1)} -> 0 | ... L23: {=INDIRECT("'"&L$2&" SCR'!D28",1)} -> 0
B24: Life catastrophe risk | C24: {=INDIRECT("'"&C$2&" SCR'!D29",1)} -> 2161439.5 | D24: {=INDIRECT("'"&D$2&" SCR'!D29",1)} -> 1735068 | E24: {=INDIRECT("'"&E$2&" SCR'!D29",1)} -> 7891.4867 | F24: {=INDIRECT("'"&F$2&" SCR'!D29",1)} -> 2578848.4 | G24: {=INDIRECT("'"&G$2&" SCR'!D29",1)} -> 2467164.2 | H24: {=INDIRECT("'"&H$2&" SCR'!D29",1)} -> 2467164.2 | I24: {=INDIRECT("'"&I$2&" SCR'!D29",1)} -> 3204977.1 | J24: {=INDIRECT("'"&J$2&" SCR'!D29",1)} -> 3394707.3 | ... L24: {=INDIRECT("'"&L$2&" SCR'!D29",1)} -> 2878720.4
B25: NSLT Health UW Module | C25: {=INDIRECT("'"&C$2&" SCR'!D35",1)} -> 184352.07 | D25: {=INDIRECT("'"&D$2&" SCR'!D35",1)} -> 10800.928 | E25: {=INDIRECT("'"&E$2&" SCR'!D35",1)} -> 1182.2288 | F25: {=INDIRECT("'"&F$2&" SCR'!D35",1)} -> 891.22211 | G25: {=INDIRECT("'"&G$2&" SCR'!D35",1)} -> 220217.61 | H25: {=INDIRECT("'"&H$2&" SCR'!D35",1)} -> 220217.61 | I25: {=INDIRECT("'"&I$2&" SCR'!D35",1)} -> 1189624.4 | J25: {=INDIRECT("'"&J$2&" SCR'!D35",1)} -> 1146833.4 | ... L25: {=INDIRECT("'"&L$2&" SCR'!D35",1)} -> 1461661.4
B26: P&R | C26: {=INDIRECT("'"&C$2&" SCR'!D33",1)} -> 184352.07 | D26: {=INDIRECT("'"&D$2&" SCR'!D33",1)} -> 10800.928 | E26: {=INDIRECT("'"&E$2&" SCR'!D33",1)} -> 1182.2288 | F26: {=INDIRECT("'"&F$2&" SCR'!D33",1)} -> 891.22211 | G26: {=INDIRECT("'"&G$2&" SCR'!D33",1)} -> 299.439 | H26: {=INDIRECT("'"&H$2&" SCR'!D33",1)} -> 299.439 | I26: {=INDIRECT("'"&I$2&" SCR'!D33",1)} -> 878436.93 | J26: {=INDIRECT("'"&J$2&" SCR'!D33",1)} -> 828777.07 | ... L26: {=INDIRECT("'"&L$2&" SCR'!D33",1)} -> 1139420.4
B27: CAT | C27: {=INDIRECT("'"&C$2&" SCR'!D34",1)} -> 0 | D27: {=INDIRECT("'"&D$2&" SCR'!D34",1)} -> 0 | E27: {=INDIRECT("'"&E$2&" SCR'!D34",1)} -> 0 | F27: {=INDIRECT("'"&F$2&" SCR'!D34",1)} -> 0 | G27: {=INDIRECT("'"&G$2&" SCR'!D34",1)} -> 220142.56 | H27: {=INDIRECT("'"&H$2&" SCR'!D34",1)} -> 220142.56 | I27: {=INDIRECT("'"&I$2&" SCR'!D34",1)} -> 612125.74 | J27: {=INDIRECT("'"&J$2&" SCR'!D34",1)} -> 612125.44 | ... L27: {=INDIRECT("'"&L$2&" SCR'!D34",1)} -> 673955.51
B31: Module | C31: Annual 2023 | D31: Q1 2024 | E31: Q2 2024 | F31: Q3 2024 | G31: Q4 2024 | H31: Annual 2024 | I31: Q1 2025 | J31: Q2 2025 | K31: =+K2 -> Q3 2025 | L31: =+L2 -> Q4 2025
B32: SCR Market | C32: =+C3 -> 8233855.4 | D32: =+D3 -> 7182534.1 | E32: =+E3 -> 11082360 | F32: =+F3 -> 8308018.7 | G32: =+G3 -> 6918653.5 | H32: =+H3 -> 6585249.8 | I32: =+I3 -> 8420689.2 | J32: =+J3 -> 5427000.6 | ... L32: =+L3 -> 7761761.2
B33: SCR CDR | C33: =+C10 -> 23265978 | D33: =+D10 -> 24901714 | E33: =+E10 -> 25501675 | F33: =+F10 -> 22432772 | G33: =+G10 -> 22319755 | H33: =+H10 -> 22455981 | I33: =+I10 -> 20521525 | J33: =+J10 -> 18369372 | ... L33: =+L10 -> 15140754
B34: SCR Life UW | C34: =+C17 -> 2852330.8 | D34: =+D17 -> 3072516.5 | E34: =+E17 -> 1248826.7 | F34: =+F17 -> 3251136.8 | G34: =+G17 -> 2940703.5 | H34: =+H17 -> 2940703.5 | I34: =+I17 -> 4300319.7 | J34: =+J17 -> 3732229.1 | ... L34: =+L17 -> 3181959.1
B35: SCR Health UW | C35: =+C25 -> 184352.07 | D35: =+D25 -> 10800.928 | E35: =+E25 -> 1182.2288 | F35: =+F25 -> 891.22211 | G35: =+G25 -> 220217.61 | H35: =+H25 -> 220217.61 | I35: =+I25 -> 1189624.4 | J35: =+J25 -> 1146833.4 | ... L35: =+L25 -> 1461661.4
B36: SCR Non-Life UW | C36: =+C13 -> 15149921 | D36: =+D13 -> 13598443 | E36: =+E13 -> 14555782 | F36: =+F13 -> 14231179 | G36: =+G13 -> 9076689 | H36: =+H13 -> 9376848.1 | I36: =+I13 -> 8954534.7 | J36: =+J13 -> 8599766.9 | ... L36: =+L13 -> 7439716.3
B37: Diversified BSCR | C37: {=INDIRECT("'"&C$2&" SCR'!D46",1)} -> 37490207 | D37: {=INDIRECT("'"&D$2&" SCR'!D46",1)} -> 37315020 | E37: {=INDIRECT("'"&E$2&" SCR'!D46",1)} -> 40032647 | F37: {=INDIRECT("'"&F$2&" SCR'!D46",1)} -> 36150828 | G37: {=INDIRECT("'"&G$2&" SCR'!D46",1)} -> 31541334 | H37: {=INDIRECT("'"&H$2&" SCR'!D46",1)} -> 31715301 | I37: {=INDIRECT("'"&I$2&" SCR'!D46",1)} -> 31336898 | J37: {=INDIRECT("'"&J$2&" SCR'!D46",1)} -> 27339205 | ... L37: {=INDIRECT("'"&L$2&" SCR'!D46",1)} -> 24756289
B38: Operational Risk | C38: {=INDIRECT("'"&C$2&" SCR'!D49",1)} -> 5557503.8 | D38: {=INDIRECT("'"&D$2&" SCR'!D49",1)} -> 5183192.2 | E38: {=INDIRECT("'"&E$2&" SCR'!D49",1)} -> 5972583 | F38: {=INDIRECT("'"&F$2&" SCR'!D49",1)} -> 7075055.7 | G38: {=INDIRECT("'"&G$2&" SCR'!D49",1)} -> 8923159.1 | H38: {=INDIRECT("'"&H$2&" SCR'!D49",1)} -> 8923159.1 | I38: {=INDIRECT("'"&I$2&" SCR'!D49",1)} -> 7820065.7 | J38: {=INDIRECT("'"&J$2&" SCR'!D49",1)} -> 6411779.1 | ... L38: {=INDIRECT("'"&L$2&" SCR'!D49",1)} -> 6157344.6
B39: LACDT | C39: {=INDIRECT("'"&C$2&" SCR'!D50",1)} -> -9758661.4 | D39: {=INDIRECT("'"&D$2&" SCR'!D50",1)} -> -9037629 | E39: {=INDIRECT("'"&E$2&" SCR'!D50",1)} -> -9439274.9 | F39: {=INDIRECT("'"&F$2&" SCR'!D50",1)} -> -9914265.9 | G39: {=INDIRECT("'"&G$2&" SCR'!D50",1)} -> -9166688.4 | H39: {=INDIRECT("'"&H$2&" SCR'!D50",1)} -> -9042430.5 | I39: {=INDIRECT("'"&I$2&" SCR'!D50",1)} -> -8673872.2 | J39: {=INDIRECT("'"&J$2&" SCR'!D50",1)} -> -8056359.9 | ... L39: {=INDIRECT("'"&L$2&" SCR'!D50",1)} -> -7379084.3
B40: SCR | C40: {=INDIRECT("'"&C$2&" SCR'!D51",1)} -> 33289050 | D40: {=INDIRECT("'"&D$2&" SCR'!D51",1)} -> 33460583 | E40: {=INDIRECT("'"&E$2&" SCR'!D51",1)} -> 36565955 | F40: {=INDIRECT("'"&F$2&" SCR'!D51",1)} -> 33311617 | G40: {=INDIRECT("'"&G$2&" SCR'!D51",1)} -> 31297804 | H40: {=INDIRECT("'"&H$2&" SCR'!D51",1)} -> 31596029 | I40: {=INDIRECT("'"&I$2&" SCR'!D51",1)} -> 30483092 | J40: {=INDIRECT("'"&J$2&" SCR'!D51",1)} -> 25694624 | ... L40: {=INDIRECT("'"&L$2&" SCR'!D51",1)} -> 23534549
B41: Own Funds | C41: {=INDIRECT("'"&C$2&" SCR'!D53",1)} -> 63733288 | D41: {=INDIRECT("'"&D$2&" SCR'!D53",1)} -> 56422951 | E41: {=INDIRECT("'"&E$2&" SCR'!D53",1)} -> 56683978 | F41: {=INDIRECT("'"&F$2&" SCR'!D53",1)} -> 59066266 | G41: {=INDIRECT("'"&G$2&" SCR'!D53",1)} -> 56816339 | H41: {=INDIRECT("'"&H$2&" SCR'!D53",1)} -> 56442370 | I41: {=INDIRECT("'"&I$2&" SCR'!D53",1)} -> 56892155 | J41: {=INDIRECT("'"&J$2&" SCR'!D53",1)} -> 61494211 | ... L41: {=INDIRECT("'"&L$2&" SCR'!D53",1)} -> 55109757
B42: Solvency II Ratio | C42: {=INDIRECT("'"&C$2&" SCR'!D55",1)} -> 1.9145421 | D42: {=INDIRECT("'"&D$2&" SCR'!D55",1)} -> 1.6862513 | E42: {=INDIRECT("'"&E$2&" SCR'!D55",1)} -> 1.5501845 | F42: {=INDIRECT("'"&F$2&" SCR'!D55",1)} -> 1.7731431 | G42: {=INDIRECT("'"&G$2&" SCR'!D55",1)} -> 1.8153458 | H42: {=INDIRECT("'"&H$2&" SCR'!D55",1)} -> 1.7863754 | I42: {=INDIRECT("'"&I$2&" SCR'!D55",1)} -> 1.8663512 | J42: {=INDIRECT("'"&J$2&" SCR'!D55",1)} -> 2.3932715 | ... L42: {=INDIRECT("'"&L$2&" SCR'!D55",1)} -> 2.3416534

Sheet Delta changes
A1: FX Impact | E1: Currency SCR | H1: Premium Provision | K1: Other
A3: BSCR | B3: 28.5 | H3: 0.23106523 | I3: on Q1
A4: OpRisk | B4: 7
A5: LACDT | B5: -8.5 | H5: 0.28177857 | I5: Q2 USD reserves over Q1 USD reserves impact
A6: SCR | B6: =SUM(B3:B5) -> 27
A8: OF | B8: 62.77
A10: SII Ratio | B10: =+B8/B6 -> 2.3248148 | E10: 2.2867696
A11: effect | B11: =+B10-'Q2 2025 SCR'!$D$55 -> -0.068456679 | E11: =+E10-'Q2 2025 SCR'!$D$55 -> -0.1065019 | H11: =-H3*(1+H5) -> -0.29617446 | K11: =-(+'Q2 2025 SCR'!E55+SUM(B11:H11)) -> -0.055787245
A17: Q1 '25 Solvency Ratio | B17: =+'Q2 2025 SCR'!C55 -> 1.8663512
A18: Currency SCR impact | B18: =-E11 -> 0.1065019
A19: Prem. Prov. methodology impact | B19: =-H11 -> 0.29617446
A20: FX impact | B20: =-B11 -> 0.068456679
A21: All other impacts | B21: =-K11 -> 0.055787245 | C21: (IBNR release (+), receivables (+), LACDT cap (-), …)
A22: Q2 '25 Solvency Ratio | B22: =SUM(B17:B21) -> 2.3932715
